<?xml version="1.0"?>
<robot xmlns:xacro="https://www.ros.org/wiki/xacro" name="cnc_bot">

	<link name="world"></link>

	<joint name="base_joint" type="fixed">
		<origin xyz="0 0 0" rpy="0 0 0"/>
		<parent link="world"/>
		<child link="base_link"/>
	</joint>


	<link name="base_link">
		<visual>
			<origin xyz="0 0 0" rpy="0 0 0"/>
			<geometry>
				<!-- <box size="2.5 1.5 0.1" /> -->
                <mesh filename="package://urdf_example/meshes/11000005_Base_Assy.STL" scale="0.001 0.001 0.001" />
			</geometry>
			<material name="gray">
				<color rgba="0.1 0.1 0.1 1"/>
			</material>
		</visual>
		<collision>
			<origin xyz="0 0 0" rpy="0 0 0"/>
			<geometry>
				<box size="2.5 1.5 0.1" />
			</geometry>
		</collision>
		<inertial>
			<origin xyz="0 0 0.05" rpy="0 0 0"/>
			<mass value="12" />
			<inertia ixx="2.26" ixy="0.0" ixz="0.0" iyy="6.26" iyz="0.0" izz="8.5" />
		</inertial>
	 </link>

	<joint name="gantry_joint" type="prismatic">
		<origin xyz=".19475 .09149 .2109" rpy="0 0 0"/>
		<parent link="base_link"/>
		<child link="gantry_link"/>
		<axis xyz="0 1 0"/>
		<limit lower="0" upper="0.8" velocity="1" effort="1"/> 
    </joint>

   <link name="gantry_link">
        <visual>
            <origin xyz=".19475 .09149 .2109" rpy="0 0 0"/>
            <geometry>
                <!-- <box size="2.5 1.5 0.1" /> -->
                <mesh filename="package://urdf_example/meshes/11000001_Gantry_Assembly.STL" scale="0.001 0.001 0.001" />
            </geometry>
            <material name="gray">
				<color rgba="0.1 0.1 0.1 1"/>
			</material>
        </visual>
        <collision>
            <origin xyz="0 0 0.075" rpy="0 0 0"/>
            <geometry>
                <box size="0.5 0.25 0.15" />
            </geometry>
        </collision>
		<inertial>
			<origin xyz="0 0 0.05" rpy="0 0 0"/>
			<mass value="12" />
			<inertia ixx="2.26" ixy="0.0" ixz="0.0" iyy="6.26" iyz="0.0" izz="8.5" />
		</inertial>
    </link>

    <joint name="cross_joint" type="prismatic">
        <origin xyz="0 0.03 0" rpy="0 0 0"/>
        <parent link="gantry_link"/>
        <child link="cross_link"/>
        <axis xyz="1 0 0"/>
        <limit lower="0" upper="0.4" velocity="1" effort="100"/> 
    </joint>

   <link name="cross_link">
        <visual>
            <origin xyz="0 .030 0" rpy="0 0 0"/>
            <geometry>
                <!-- <box size="2.5 1.5 0.1" /> -->
                <mesh filename="package://urdf_example/meshes/X_Carriage_Assy.STL" scale="0.001 0.001 0.001" />
            </geometry>
            <material name="gray">
				<color rgba="0.1 0.1 0.1 1"/>
			</material>
        </visual>
        <collision>
            <origin xyz="0 0 0.075" rpy="0 0 0"/>
            <geometry>
                <box size="0.5 0.25 0.15" />
            </geometry>
        </collision>
		<inertial>
			<origin xyz="0 0 0.05" rpy="0 0 0"/>
			<mass value="12" />
			<inertia ixx="2.26" ixy="0.0" ixz="0.0" iyy="6.26" iyz="0.0" izz="8.5" />
		</inertial>
    </link>
	
    <joint name="z_joint" type="prismatic">
        <origin xyz="0 -0.030 0" rpy="0 0 0"/>
        <parent link="cross_link"/>
        <child link="z_link"/>
        <axis xyz="0 0 1"/>
        <limit lower="0" upper="0.1" velocity="1" effort="100"/> 
    </joint>

   <link name="z_link">
        <visual>
            <origin xyz="0 -0.030 0" rpy="0 0 0"/>
            <geometry>
                <!-- <box size="2.5 1.5 0.1" /> -->
                <mesh filename="package://urdf_example/meshes/Spindle_Assembly.STL" scale="0.001 0.001 0.001" />
            </geometry>
            <material name="white">
				<color rgba="0.9 0.9 0.9 1"/>
			</material>
        </visual>
        <collision>
            <origin xyz="0 0 0.075" rpy="0 0 0"/>
            <geometry>
                <box size="0.5 0.25 0.15" />
            </geometry>
        </collision>
		<inertial>
			<origin xyz="0 0 0.05" rpy="0 0 0"/>
			<mass value="12" />
			<inertia ixx="2.26" ixy="0.0" ixz="0.0" iyy="6.26" iyz="0.0" izz="8.5" />
		</inertial>
    </link>


</robot>